Workbook

Sheet Q1- Stations by State
A3: Row Labels | B3: Average of ev_stations
A4: MAH | B4: 1067.1707
A5: DELHI | B5: 1050.7937
A6: BIHAR | B6: 138.25926
A7: KER | B7: 135.5
A8: MP | B8: 92.4
A9: RAJ | B9: 61.0625
A10: TN | B10: 61
A11: ASSAM | B11: 58.095238
A12: KAR | B12: 45.045455
A13: AP | B13: 41.630435
A14: TNG | B14: 32.026316
A15: HARYANA | B15: 26.071429
... A22: Grand Total | B22: 243.57495

Sheet Q2- Electricity by State
A3: Row Labels | B3: Sum of total_mu
A4: DELHI | B4: 252.654
A5: MAH | B5: 157.786
A6: GUJ | B6: 59.719
A7: HARYANA | B7: 8.869384
A8: AP | B8: 8.867
A9: RAJ | B9: 5.960228
A10: CHANDIGARH | B10: 5.108264
A11: WB | B11: 4.862
A12: KAR | B12: 3.88148
A13: ASSAM | B13: 3.579994
A14: TNG | B14: 3.418
A15: BIHAR | B15: 3.244
... A22: Grand Total | B22: 523.59109

Sheet Q3 (a)- Yearly Trend
A3: Row Labels | B3: Sum of ev_stations | C3: Sum of total_mu | D3: Growth % | E3: Growth %
A4: 2022-23 | B4: 37858 | C4: 139.35414 | D4: no growth for the first year, it's the base | E4: -
A5: 2023-24 | B5: 90506 | C5: 384.23694 | D5: =(B5-B4)/B4 -> 1.3906704 | E5: =(C5-C4)/C4 -> 1.7572696
A6: Grand Total | B6: 128364 | C6: 523.59109

Sheet Q3 (b)- Monthly Trend
A3: Sum of ev_stations
B4: 2022-23 | C4: 2023-24 | D4: Grand Total
A5: 1 | C5: 6365 | D5: 6365
A6: 2 | C6: 6500 | D6: 6500
A7: 3 | C7: 6714 | D7: 6714
A8: 4 | B8: 2744 | C8: 7289 | D8: 10033
A9: 5 | B9: 2852 | C9: 7554 | D9: 10406
A10: 6 | B10: 2947 | C10: 7730 | D10: 10677
A11: 7 | B11: 3006 | C11: 7796 | D11: 10802
A12: 8 | B12: 3173 | C12: 13113 | D12: 16286
A13: 9 | B13: 5533 | C13: 9420 | D13: 14953
A14: 10 | B14: 5616 | C14: 9434 | D14: 15050
A15: 11 | B15: 5785 | C15: 8591 | D15: 14376
A16: 12 | B16: 6202 | D16: 6202
A17: Grand Total | B17: 37858 | C17: 90506 | D17: 128364

Sheet Q4- Utilisation Index
A1: State | B1: Total EV Electricity (kWh) | C1: Total EV Stations | D1: Utilisation Index (kWh per station) | E1: Tier
A2: HARYANA | B2: =SUMIF('8486_cleaned_analysis'!F:F,A2,'8486_cleaned_analysis'!J:J) -> 8869709 | C2: =SUMIF('8486_cleaned_analysis'!F:F,A2,'8486_cleaned_analysis'!H:H) -> 730 | D2: =IF(C2>0,B2/C2,"") -> 12150.286 | E2: =IF(D2>5000,"High",IF(D2>1000,"Medium","Low")) -> High
A3: RAJ | B3: =SUMIF('8486_cleaned_analysis'!F:F,A3,'8486_cleaned_analysis'!J:J) -> 4979872 | C3: =SUMIF('8486_cleaned_analysis'!F:F,A3,'8486_cleaned_analysis'!H:H) -> 977 | D3: =IF(C3>0,B3/C3,"") -> 5097.1054 | E3: =IF(D3>5000,"High",IF(D3>1000,"Medium","Low")) -> High
A4: TN | B4: =SUMIF('8486_cleaned_analysis'!F:F,A4,'8486_cleaned_analysis'!J:J) -> 2309863 | C4: =SUMIF('8486_cleaned_analysis'!F:F,A4,'8486_cleaned_analysis'!H:H) -> 671 | D4: =IF(C4>0,B4/C4,"") -> 3442.4188 | E4: =IF(D4>5000,"High",IF(D4>1000,"Medium","Low")) -> Medium
A5: CHANDIGARH | B5: =SUMIF('8486_cleaned_analysis'!F:F,A5,'8486_cleaned_analysis'!J:J) -> 360032 | C5: =SUMIF('8486_cleaned_analysis'!F:F,A5,'8486_cleaned_analysis'!H:H) -> 107 | D5: =IF(C5>0,B5/C5,"") -> 3364.785 | E5: =IF(D5>5000,"High",IF(D5>1000,"Medium","Low")) -> Medium
A6: DELHI | B6: =SUMIF('8486_cleaned_analysis'!F:F,A6,'8486_cleaned_analysis'!J:J) -> 181260299 | C6: =SUMIF('8486_cleaned_analysis'!F:F,A6,'8486_cleaned_analysis'!H:H) -> 66200 | D6: =IF(C6>0,B6/C6,"") -> 2738.071 | E6: =IF(D6>5000,"High",IF(D6>1000,"Medium","Low")) -> Medium
A7: ASSAM | B7: =SUMIF('8486_cleaned_analysis'!F:F,A7,'8486_cleaned_analysis'!J:J) -> 3046559 | C7: =SUMIF('8486_cleaned_analysis'!F:F,A7,'8486_cleaned_analysis'!H:H) -> 1220 | D7: =IF(C7>0,B7/C7,"") -> 2497.1795 | E7: =IF(D7>5000,"High",IF(D7>1000,"Medium","Low")) -> Medium
A8: JHARKHAND | B8: =SUMIF('8486_cleaned_analysis'!F:F,A8,'8486_cleaned_analysis'!J:J) -> 14360 | C8: =SUMIF('8486_cleaned_analysis'!F:F,A8,'8486_cleaned_analysis'!H:H) -> 8 | D8: =IF(C8>0,B8/C8,"") -> 1795 | E8: =IF(D8>5000,"High",IF(D8>1000,"Medium","Low")) -> Medium
A9: UP | B9: =SUMIF('8486_cleaned_analysis'!F:F,A9,'8486_cleaned_analysis'!J:J) -> 35564 | C9: =SUMIF('8486_cleaned_analysis'!F:F,A9,'8486_cleaned_analysis'!H:H) -> 36 | D9: =IF(C9>0,B9/C9,"") -> 987.88889 | E9: =IF(D9>5000,"High",IF(D9>1000,"Medium","Low")) -> Low
A10: GUJ | B10: =SUMIF('8486_cleaned_analysis'!F:F,A10,'8486_cleaned_analysis'!J:J) -> 1479363 | C10: =SUMIF('8486_cleaned_analysis'!F:F,A10,'8486_cleaned_analysis'!H:H) -> 1655 | D10: =IF(C10>0,B10/C10,"") -> 893.87492 | E10: =IF(D10>5000,"High",IF(D10>1000,"Medium","Low")) -> Low
A11: TNG | B11: =SUMIF('8486_cleaned_analysis'!F:F,A11,'8486_cleaned_analysis'!J:J) -> 932007 | C11: =SUMIF('8486_cleaned_analysis'!F:F,A11,'8486_cleaned_analysis'!H:H) -> 1217 | D11: =IF(C11>0,B11/C11,"") -> 765.82334 | E11: =IF(D11>5000,"High",IF(D11>1000,"Medium","Low")) -> Low
A12: KER | B12: =SUMIF('8486_cleaned_analysis'!F:F,A12,'8486_cleaned_analysis'!J:J) -> 1695501 | C12: =SUMIF('8486_cleaned_analysis'!F:F,A12,'8486_cleaned_analysis'!H:H) -> 2439 | D12: =IF(C12>0,B12/C12,"") -> 695.16236 | E12: =IF(D12>5000,"High",IF(D12>1000,"Medium","Low")) -> Low
A13: BIHAR | B13: =SUMIF('8486_cleaned_analysis'!F:F,A13,'8486_cleaned_analysis'!J:J) -> 1758620 | C13: =SUMIF('8486_cleaned_analysis'!F:F,A13,'8486_cleaned_analysis'!H:H) -> 3733 | D13: =IF(C13>0,B13/C13,"") -> 471.10099 | E13: =IF(D13>5000,"High",IF(D13>1000,"Medium","Low")) -> Low
... A19: MAH | B19: =SUMIF('8486_cleaned_analysis'!F:F,A19,'8486_cleaned_analysis'!J:J) -> 8078812 | C19: =SUMIF('8486_cleaned_analysis'!F:F,A19,'8486_cleaned_analysis'!H:H) -> 43754 | D19: =IF(C19>0,B19/C19,"") -> 184.64168 | E19: =IF(D19>5000,"High",IF(D19>1000,"Medium","Low")) -> Low

Sheet 8486_cleaned_analysis
A1: Country | B1: financial_year | C1: calendar_year | D1: calendar_month | E1: DISCOM | F1: State | G1: city | H1: ev_stations | I1: hd_stations | J1: ev_kwh | K1: hd_kwh | L1: total_mu
A2: India | B2: 2023-24 | C2: 2023 | D2: 8 | E2: HESCOM | F2: KAR | G2: hubli | H2: 12 | I2: 0 | J2: 12807 | K2: 0 | L2: 0.013
A3: India | B3: 2023-24 | C3: 2023 | D3: 9 | E3: HESCOM | F3: KAR | G3: hubli | H3: 22 | I3: 0 | J3: 11790 | K3: 0 | L3: 0.012
A4: India | B4: 2023-24 | C4: 2023 | D4: 9 | E4: APEPDCL | F4: AP | G4: visakhapatnam, rajmahendravaram, west godavari, srikakulam, vizianagaram | H4: 70 | I4: 0 | J4: 22216 | K4: 0 | L4: 0.022
A5: India | B5: 2023-24 | C5: 2023 | D5: 9 | E5: NBPDCL | F5: BIHAR | G5: patna | H5: 204 | I5: 0 | J5: 32693 | K5: 0 | L5: 0.033
A6: India | B6: 2023-24 | C6: 2023 | D6: 9 | E6: GESCOM | F6: KAR | G6: kalaburgi | H6: 1 | I6: 0 | J6: 1498 | K6: 0 | L6: 0.001
A7: India | B7: 2023-24 | C7: 2023 | D7: 9 | E7: DGVCL | F7: GUJ | G7: surat city, navsari, vapi-town, haldarva, bharuch east, kavadiya colony | H7: 53 | I7: 13 | J7: 48121 | K7: 1615706 | L7: 1.664
A8: India | B8: 2023-24 | C8: 2023 | D8: 9 | E8: APEPDCL | F8: AP | G8: visakhapatnam, rajmahendravaram, west godavari, srikakulam, vizianagaram | H8: 70 | I8: 0 | J8: 22216 | K8: 0 | L8: 0.022
A9: India | B9: 2023-24 | C9: 2023 | D9: 9 | E9: Tata Power-DDL | F9: DELHI | G9: new delhi | H9: 639 | I9: 5 | J9: 3220000 | K9: 810000 | L9: 4.03
A10: India | B10: 2023-24 | C10: 2023 | D10: 9 | E10: MPMKVVCL | F10: MP | G10: bhopal city, gwalior city, betul, guna, harda, itarsi, narmadapuram, bareli, raisen, narsinghgarh, zeerapur, ashta, vidisha | H10: 97 | I10: 1 | J10: 25358 | K10: 218128 | L10: 0.243
A11: India | B11: 2023-24 | C11: 2023 | D11: 9 | E11: PGVCL | F11: GUJ | G11: rajkot, surendranagar, junagadh, jamnagar, morbi, botad | H11: 25 | I11: 3 | J11: 61807 | K11: 469488 | L11: 0.531
A12: India | B12: 2023-24 | C12: 2023 | D12: 9 | E12: MESCOM | F12: KAR | G12: mangaluru, udupi, shivamogga, chikkamagaluru | H12: 67 | I12: 2 | J12: 5612 | K12: 80109 | L12: 0.086
A13: India | B13: 2023-24 | C13: 2023 | D13: 9 | E13: APEPDCL | F13: AP | G13: visakhapatnam, rajmahendravaram, west godavari, srikakulam, vizianagaram | H13: 70 | I13: 0 | J13: 22216 | K13: 0 | L13: 0.022
... A19: India | B19: 2023-24 | C19: 2023 | D19: 8 | E19: SBPDCL | F19: BIHAR | G19: patna | H19: 223 | I19: 2 | J19: 277174 | K19: 225321 | L19: 0.502
A20: India | B20: 2023-24 | C20: 2023 | D20: 8 | E20: DVC | F20: JHARKHAND | G20: maithon, dhanbad | I20: 0 | J20: 3590 | K20: 0 | L20: 0
A21: India | B21: 2023-24 | C21: 2023 | D21: 8 | E21: CESC | F21: WB | G21: kolkata | H21: 12 | I21: 11 | J21: 2098 | K21: 244605 | L21: 0.247
A22: India | B22: 2023-24 | C22: 2023 | D22: 8 | E22: APDCL | F22: ASSAM | G22: badarpur, karimganj, kokrajhar, nagaon, silchar, guwahati, tezpur | H22: 99 | I22: 9 | J22: 221296 | K22: 19714 | L22: 0.241
A23: India | B23: 2023-24 | C23: 2023 | D23: 1 | E23: Brihan Mumbai Electric Supply Company (BEST) | F23: MAH | G23: mumbai (best) | H23: 17 | I23: 10 | J23: 37699 | K23: 1656478 | L23: 1.694
A24: India | B24: 2023-24 | C24: 2023 | D24: 1 | E24: MESCOM | F24: KAR | G24: mangaluru, udupi, shivamogga, chikkamagaluru | H24: 63 | I24: 0 | J24: 5037 | K24: 0 | L24: 0.005
A25: India | B25: 2023-24 | C25: 2023 | D25: 1 | E25: BYPL | F25: DELHI | G25: new delhi | H25: 994 | I25: 2 | J25: 1761898 | K25: 613200 | L25: 2.375
A26: India | B26: 2023-24 | C26: 2023 | D26: 1 | E26: UGVCL | F26: GUJ | G26: hebatpur, bavla(ramnagar), fedra, dholasan, asal, modasa, majadar, nugar, rangpur | H26: 12 | I26: 0 | J26: 2767 | K26: 0 | L26: 0.003
A27: India | B27: 2023-24 | C27: 2023 | D27: 1 | E27: APDCL | F27: ASSAM | G27: badarpur, karimganj, kokrajhar, nagaon, silchar, guwahati, tezpur | H27: 53 | I27: 3 | J27: 94498 | K27: 27821 | L27: 0.122
A28: India | B28: 2023-24 | C28: 2023 | D28: 1 | E28: SBPDCL | F28: BIHAR | G28: patna | H28: 78 | I28: 0 | J28: 6000 | K28: 0 | L28: 0.006
A29: India | B29: 2023-24 | C29: 2023 | D29: 1 | E29: Torrent Power | F29: GUJ | G29: ahemdabad | H29: 10 | I29: 6 | J29: 4612 | K29: 1452970 | L29: 1.458
A30: India | B30: 2022-23 | C30: 2022 | D30: 4 | E30: TANGEDCO | F30: TN | G30: coimbatore, villupuram, tirunelveli, chennai north, vellore | H30: 30 | I30: 0 | J30: 53523 | K30: 0 | L30: 0.054
A31: India | B31: 2022-23 | C31: 2022 | D31: 4 | E31: MSEDCL | F31: MAH | G31: navi mumbai, pune, thane, nagpur | H31: 48 | I31: 4 | J31: 1 | K31: 133796 | L31: 0.134
A32: India | B32: 2022-23 | C32: 2022 | D32: 4 | E32: APEPDCL | F32: AP | G32: visakhapatnam, rajmahendravaram, west godavari, srikakulam, vizianagaram | H32: 33 | I32: 0 | J32: 6101 | K32: 0 | L32: 0.006
... A51: India | B51: 2023-24 | C51: 2023 | D51: 4 | E51: Noida Power Company Ltd. (NPCL) | F51: UP | G51: greater noida | H51: 3 | I51: 0 | J51: 117 | K51: 0 | L51: 0
A52: India | B52: 2023-24 | C52: 2023 | D52: 4 | E52: JDVVNL | F52: RAJ | G52: pali | L52: 0
A53: India | B53: 2023-24 | C53: 2023 | D53: 4 | E53: TSNPDCL | F53: TNG | G53: adilabad, hanamkonda, kamareddy, karimnagar, khammam, mahabubabad, nirmal, nazimabad, pdeapally, warangal | H53: 32 | I53: 0 | J53: 8015 | K53: 0 | L53: 0.008
A54: India | B54: 2023-24 | C54: 2023 | D54: 4 | E54: BRPL | F54: DELHI | G54: new delhi | H54: 1666 | I54: 1 | J54: 4044558 | K54: 864960 | L54: 4.91
A55: India | B55: 2023-24 | C55: 2023 | D55: 4 | E55: TANGEDCO | F55: TN | G55: coimbatore, villupuram, tirunelveli, chennai north, vellore | L55: 0
A56: India | B56: 2023-24 | C56: 2023 | D56: 4 | E56: AVVNL | F56: RAJ | G56: ajmer | H56: 24 | I56: 0 | J56: 10674 | K56: 0 | L56: 0.011
A57: India | B57: 2023-24 | C57: 2023 | D57: 4 | E57: KSEB | F57: KER | G57: thiruvananthapuram, ernakulam, kozhikode | H57: 258 | I57: 4 | J57: 103348 | K57: 29360 | L57: 0.133
A58: India | B58: 2023-24 | C58: 2023 | D58: 4 | E58: NBPDCL | F58: BIHAR | G58: patna | H58: 107 | I58: 0 | J58: 9338 | K58: 0 | L58: 0.009
A59: India | B59: 2023-24 | C59: 2023 | D59: 4 | E59: BYPL | F59: DELHI | G59: new delhi | H59: 1024 | I59: 2 | J59: 2214653 | K59: 823223 | L59: 3.038
A60: India | B60: 2023-24 | C60: 2023 | D60: 4 | E60: SBPDCL | F60: BIHAR | G60: patna | H60: 103 | I60: 2 | J60: 142024 | K60: 196093 | L60: 0.338
A61: India | B61: 2023-24 | C61: 2023 | D61: 4 | E61: UHBVN | F61: HARYANA | G61: panchkula, karnal, kaithal, sonipat, ambala, kurukshetra | H61: 8 | I61: 0 | J61: 11948 | K61: 0 | L61: 0.012
A62: India | B62: 2023-24 | C62: 2023 | D62: 4 | E62: PGVCL | F62: GUJ | G62: rajkot, surendranagar, junagadh, jamnagar, morbi, botad | H62: 19 | I62: 3 | J62: 14876 | K62: 441657 | L62: 0.457
A63: India | B63: 2023-24 | C63: 2023 | D63: 4 | E63: JVVNL | F63: RAJ | G63: alwar, dausa, jcc, jpdc | H63: 130 | I63: 7 | J63: 298987 | K63: 56387 | L63: 0.355
...
